// Bug happens on JVM 
// FILE: tmp0.kt


val p = 
try {}
catch(e: AssertionError){
{
try {}
catch(e: RuntimeException){
::foo
}
}
}

